{"summary": {"file_name": "windvectors.csv"}, "goals": [{"index": 0, "question": "What is the distribution of wind speed?", "visualization": "Histogram of wind_speed", "rationale": "This visualization will help us understand the frequency of different wind speeds and identify any outliers."}, {"index": 1, "question": "What is the relationship between wind speed and wind direction?", "visualization": "Scatter plot of wind_speed vs wind_direction", "rationale": "This visualization will help us identify any patterns or correlations between wind speed and wind direction."}, {"index": 2, "question": "What is the average wind speed by month?", "visualization": "Line chart of average wind_speed by month", "rationale": "This visualization will help us identify any seasonal trends in wind speed."}, {"index": 3, "question": "What is the distribution of wind direction?", "visualization": "Histogram of wind_direction", "rationale": "This visualization will help us understand the frequency of different wind directions and identify any outliers."}, {"index": 4, "question": "What is the relationship between wind speed and temperature?", "visualization": "Scatter plot of wind_speed vs temperature", "rationale": "This visualization will help us identify any patterns or correlations between wind speed and temperature."}], "code": [["import matplotlib.pyplot as plt\nimport pandas as pd\n\ndef plot(data: pd.DataFrame):\n    data['wind_speed'] = pd.to_numeric(data['wind_speed'], errors='coerce')\n    data = data[pd.notna(data['wind_speed'])]\n    \n    plt.hist(data['wind_speed'], bins=20, color='blue', alpha=0.7, label='Wind Speed')\n    plt.axvline(data['wind_speed'].median(), color='red', linestyle='dashed', linewidth=2, label=f\"Median: {data['wind_speed'].median():.2f}\")\n    plt.xlabel('Wind Speed')\n    plt.ylabel('Frequency')\n    plt.title('What is the distribution of wind speed?', wrap=True)\n    plt.legend()\n    return plt;\n\nchart = plot(data)"], ["import matplotlib.pyplot as plt\nimport pandas as pd\n\ndef plot(data: pd.DataFrame):\n    plt.scatter(data['wind_speed'], data['wind_direction'], alpha=0.5)\n    plt.xlabel('Wind Speed')\n    plt.ylabel('Wind Direction')\n    plt.title('What is the relationship between wind speed and wind direction?', wrap=True)\n    return plt;\n\nchart = plot(data)"], ["import matplotlib.pyplot as plt\nimport pandas as pd\n\ndef plot(data: pd.DataFrame):\n    data['date'] = pd.to_datetime(data['date'], errors='coerce')\n    data = data[pd.notna(data['date'])]\n    data['month'] = data['date'].dt.to_period('M')\n    monthly_avg_wind_speed = data.groupby('month')['wind_speed'].mean()\n\n    plt.plot(monthly_avg_wind_speed.index.to_timestamp(), monthly_avg_wind_speed, label='Average Wind Speed')\n    plt.axhline(monthly_avg_wind_speed.mean(), color='r', linestyle='--', label=f\"Overall Average: {monthly_avg_wind_speed.mean():.2f}\")\n    plt.xlabel('Month')\n    plt.ylabel('Average Wind Speed')\n    plt.title('What is the average wind speed by month?', wrap=True)\n    plt.legend()\n    plt.xticks(rotation=45)\n    return plt;\n\nchart = plot(data)"], ["import matplotlib.pyplot as plt\nimport pandas as pd\n\ndef plot(data: pd.DataFrame):\n    data['wind_direction'].plot(kind='hist', bins=20, color='blue', edgecolor='black')\n    plt.title(\"What is the distribution of wind direction?\", wrap=True)\n    plt.xlabel(\"Wind Direction\")\n    plt.ylabel(\"Frequency\")\n    plt.legend([\"Wind Direction\"])\n    return plt;\n\nchart = plot(data)"], ["import matplotlib.pyplot as plt\nimport pandas as pd\n\ndef plot(data: pd.DataFrame):\n    plt.scatter(data['wind_speed'], data['temperature'])\n    plt.xlabel('Wind Speed')\n    plt.ylabel('Temperature')\n    plt.title('What is the relationship between wind speed and temperature?', wrap=True)\n    plt.legend(['Wind Speed vs Temperature'])\n    return plt;\n\nchart = plot(data)"]], "filename": "windvectors.csv", "chart": [[{"spec": null, "status": false, "raster": null, "code": "import matplotlib.pyplot as plt\nimport pandas as pd\n\ndef plot(data: pd.DataFrame):\n    data['wind_speed'] = pd.to_numeric(data['wind_speed'], errors='coerce')\n    data = data[pd.notna(data['wind_speed'])]\n    \n    plt.hist(data['wind_speed'], bins=20, color='blue', alpha=0.7, label='Wind Speed')\n    plt.axvline(data['wind_speed'].median(), color='red', linestyle='dashed', linewidth=2, label=f\"Median: {data['wind_speed'].median():.2f}\")\n    plt.xlabel('Wind Speed')\n    plt.ylabel('Frequency')\n    plt.title('What is the distribution of wind speed?', wrap=True)\n    plt.legend()\n    return plt;\n\nchart = plot(data)", "library": "matplotlib", "error": {"message": "'wind_speed'", "traceback": "Traceback (most recent call last):\n  File \"/home/victordibia/.local/lib/python3.9/site-packages/pandas/core/indexes/base.py\", line 3621, in get_loc\n    return self._engine.get_loc(casted_key)\n  File \"pandas/_libs/index.pyx\", line 136, in pandas._libs.index.IndexEngine.get_loc\n  File \"pandas/_libs/index.pyx\", line 163, in pandas._libs.index.IndexEngine.get_loc\n  File \"pandas/_libs/hashtable_class_helper.pxi\", line 5198, in pandas._libs.hashtable.PyObjectHashTable.get_item\n  File \"pandas/_libs/hashtable_class_helper.pxi\", line 5206, in pandas._libs.hashtable.PyObjectHashTable.get_item\nKeyError: 'wind_speed'\n\nThe above exception was the direct cause of the following exception:\n\nTraceback (most recent call last):\n  File \"/home/victordibia/projects/projectlida/lida/lib/lida/modules/executor.py\", line 144, in execute\n    exec(code, ex_locals)\n  File \"<string>\", line 16, in <module>\n  File \"<string>\", line 5, in plot\n  File \"/home/victordibia/.local/lib/python3.9/site-packages/pandas/core/frame.py\", line 3505, in __getitem__\n    indexer = self.columns.get_loc(key)\n  File \"/home/victordibia/.local/lib/python3.9/site-packages/pandas/core/indexes/base.py\", line 3623, in get_loc\n    raise KeyError(key) from err\nKeyError: 'wind_speed'\n"}}], [{"spec": null, "status": false, "raster": null, "code": "import matplotlib.pyplot as plt\nimport pandas as pd\n\ndef plot(data: pd.DataFrame):\n    plt.scatter(data['wind_speed'], data['wind_direction'], alpha=0.5)\n    plt.xlabel('Wind Speed')\n    plt.ylabel('Wind Direction')\n    plt.title('What is the relationship between wind speed and wind direction?', wrap=True)\n    return plt;\n\nchart = plot(data)", "library": "matplotlib", "error": {"message": "'wind_speed'", "traceback": "Traceback (most recent call last):\n  File \"/home/victordibia/.local/lib/python3.9/site-packages/pandas/core/indexes/base.py\", line 3621, in get_loc\n    return self._engine.get_loc(casted_key)\n  File \"pandas/_libs/index.pyx\", line 136, in pandas._libs.index.IndexEngine.get_loc\n  File \"pandas/_libs/index.pyx\", line 163, in pandas._libs.index.IndexEngine.get_loc\n  File \"pandas/_libs/hashtable_class_helper.pxi\", line 5198, in pandas._libs.hashtable.PyObjectHashTable.get_item\n  File \"pandas/_libs/hashtable_class_helper.pxi\", line 5206, in pandas._libs.hashtable.PyObjectHashTable.get_item\nKeyError: 'wind_speed'\n\nThe above exception was the direct cause of the following exception:\n\nTraceback (most recent call last):\n  File \"/home/victordibia/projects/projectlida/lida/lib/lida/modules/executor.py\", line 144, in execute\n    exec(code, ex_locals)\n  File \"<string>\", line 11, in <module>\n  File \"<string>\", line 5, in plot\n  File \"/home/victordibia/.local/lib/python3.9/site-packages/pandas/core/frame.py\", line 3505, in __getitem__\n    indexer = self.columns.get_loc(key)\n  File \"/home/victordibia/.local/lib/python3.9/site-packages/pandas/core/indexes/base.py\", line 3623, in get_loc\n    raise KeyError(key) from err\nKeyError: 'wind_speed'\n"}}], [{"spec": null, "status": false, "raster": null, "code": "import matplotlib.pyplot as plt\nimport pandas as pd\n\ndef plot(data: pd.DataFrame):\n    data['date'] = pd.to_datetime(data['date'], errors='coerce')\n    data = data[pd.notna(data['date'])]\n    data['month'] = data['date'].dt.to_period('M')\n    monthly_avg_wind_speed = data.groupby('month')['wind_speed'].mean()\n\n    plt.plot(monthly_avg_wind_speed.index.to_timestamp(), monthly_avg_wind_speed, label='Average Wind Speed')\n    plt.axhline(monthly_avg_wind_speed.mean(), color='r', linestyle='--', label=f\"Overall Average: {monthly_avg_wind_speed.mean():.2f}\")\n    plt.xlabel('Month')\n    plt.ylabel('Average Wind Speed')\n    plt.title('What is the average wind speed by month?', wrap=True)\n    plt.legend()\n    plt.xticks(rotation=45)\n    return plt;\n\nchart = plot(data)", "library": "matplotlib", "error": {"message": "'date'", "traceback": "Traceback (most recent call last):\n  File \"/home/victordibia/.local/lib/python3.9/site-packages/pandas/core/indexes/base.py\", line 3621, in get_loc\n    return self._engine.get_loc(casted_key)\n  File \"pandas/_libs/index.pyx\", line 136, in pandas._libs.index.IndexEngine.get_loc\n  File \"pandas/_libs/index.pyx\", line 163, in pandas._libs.index.IndexEngine.get_loc\n  File \"pandas/_libs/hashtable_class_helper.pxi\", line 5198, in pandas._libs.hashtable.PyObjectHashTable.get_item\n  File \"pandas/_libs/hashtable_class_helper.pxi\", line 5206, in pandas._libs.hashtable.PyObjectHashTable.get_item\nKeyError: 'date'\n\nThe above exception was the direct cause of the following exception:\n\nTraceback (most recent call last):\n  File \"/home/victordibia/projects/projectlida/lida/lib/lida/modules/executor.py\", line 144, in execute\n    exec(code, ex_locals)\n  File \"<string>\", line 19, in <module>\n  File \"<string>\", line 5, in plot\n  File \"/home/victordibia/.local/lib/python3.9/site-packages/pandas/core/frame.py\", line 3505, in __getitem__\n    indexer = self.columns.get_loc(key)\n  File \"/home/victordibia/.local/lib/python3.9/site-packages/pandas/core/indexes/base.py\", line 3623, in get_loc\n    raise KeyError(key) from err\nKeyError: 'date'\n"}}], [{"spec": null, "status": false, "raster": null, "code": "import matplotlib.pyplot as plt\nimport pandas as pd\n\ndef plot(data: pd.DataFrame):\n    data['wind_direction'].plot(kind='hist', bins=20, color='blue', edgecolor='black')\n    plt.title(\"What is the distribution of wind direction?\", wrap=True)\n    plt.xlabel(\"Wind Direction\")\n    plt.ylabel(\"Frequency\")\n    plt.legend([\"Wind Direction\"])\n    return plt;\n\nchart = plot(data)", "library": "matplotlib", "error": {"message": "'wind_direction'", "traceback": "Traceback (most recent call last):\n  File \"/home/victordibia/.local/lib/python3.9/site-packages/pandas/core/indexes/base.py\", line 3621, in get_loc\n    return self._engine.get_loc(casted_key)\n  File \"pandas/_libs/index.pyx\", line 136, in pandas._libs.index.IndexEngine.get_loc\n  File \"pandas/_libs/index.pyx\", line 163, in pandas._libs.index.IndexEngine.get_loc\n  File \"pandas/_libs/hashtable_class_helper.pxi\", line 5198, in pandas._libs.hashtable.PyObjectHashTable.get_item\n  File \"pandas/_libs/hashtable_class_helper.pxi\", line 5206, in pandas._libs.hashtable.PyObjectHashTable.get_item\nKeyError: 'wind_direction'\n\nThe above exception was the direct cause of the following exception:\n\nTraceback (most recent call last):\n  File \"/home/victordibia/projects/projectlida/lida/lib/lida/modules/executor.py\", line 144, in execute\n    exec(code, ex_locals)\n  File \"<string>\", line 12, in <module>\n  File \"<string>\", line 5, in plot\n  File \"/home/victordibia/.local/lib/python3.9/site-packages/pandas/core/frame.py\", line 3505, in __getitem__\n    indexer = self.columns.get_loc(key)\n  File \"/home/victordibia/.local/lib/python3.9/site-packages/pandas/core/indexes/base.py\", line 3623, in get_loc\n    raise KeyError(key) from err\nKeyError: 'wind_direction'\n"}}], [{"spec": null, "status": false, "raster": null, "code": "import matplotlib.pyplot as plt\nimport pandas as pd\n\ndef plot(data: pd.DataFrame):\n    plt.scatter(data['wind_speed'], data['temperature'])\n    plt.xlabel('Wind Speed')\n    plt.ylabel('Temperature')\n    plt.title('What is the relationship between wind speed and temperature?', wrap=True)\n    plt.legend(['Wind Speed vs Temperature'])\n    return plt;\n\nchart = plot(data)", "library": "matplotlib", "error": {"message": "'wind_speed'", "traceback": "Traceback (most recent call last):\n  File \"/home/victordibia/.local/lib/python3.9/site-packages/pandas/core/indexes/base.py\", line 3621, in get_loc\n    return self._engine.get_loc(casted_key)\n  File \"pandas/_libs/index.pyx\", line 136, in pandas._libs.index.IndexEngine.get_loc\n  File \"pandas/_libs/index.pyx\", line 163, in pandas._libs.index.IndexEngine.get_loc\n  File \"pandas/_libs/hashtable_class_helper.pxi\", line 5198, in pandas._libs.hashtable.PyObjectHashTable.get_item\n  File \"pandas/_libs/hashtable_class_helper.pxi\", line 5206, in pandas._libs.hashtable.PyObjectHashTable.get_item\nKeyError: 'wind_speed'\n\nThe above exception was the direct cause of the following exception:\n\nTraceback (most recent call last):\n  File \"/home/victordibia/projects/projectlida/lida/lib/lida/modules/executor.py\", line 144, in execute\n    exec(code, ex_locals)\n  File \"<string>\", line 12, in <module>\n  File \"<string>\", line 5, in plot\n  File \"/home/victordibia/.local/lib/python3.9/site-packages/pandas/core/frame.py\", line 3505, in __getitem__\n    indexer = self.columns.get_loc(key)\n  File \"/home/victordibia/.local/lib/python3.9/site-packages/pandas/core/indexes/base.py\", line 3623, in get_loc\n    raise KeyError(key) from err\nKeyError: 'wind_speed'\n"}}]]}