{"summary": {"file_name": "flare-dependencies.json"}, "goals": [{"index": 0, "question": "What is the distribution of package sizes in the flare-dependencies dataset?", "visualization": "Histogram of package sizes", "rationale": "This visualization will help us understand the range of package sizes in the dataset and identify any outliers."}, {"index": 1, "question": "What is the most common type of dependency in the flare-dependencies dataset?", "visualization": "Bar chart of dependency types", "rationale": "This visualization will help us understand the distribution of dependency types and identify any patterns or trends."}, {"index": 2, "question": "What is the relationship between package size and number of dependencies in the flare-dependencies dataset?", "visualization": "Scatter plot of package size vs. number of dependencies", "rationale": "This visualization will help us understand if there is any correlation between package size and number of dependencies, which could be useful for optimizing package design."}, {"index": 3, "question": "What is the distribution of package names in the flare-dependencies dataset?", "visualization": "Word cloud of package names", "rationale": "This visualization will help us understand the most common package names in the dataset and identify any patterns or trends."}, {"index": 4, "question": "What is the distribution of package versions in the flare-dependencies dataset?", "visualization": "Bar chart of package versions", "rationale": "This visualization will help us understand the most common package versions in the dataset and identify any patterns or trends."}], "code": [["import matplotlib.pyplot as plt\nimport pandas as pd\n\ndef plot(data: pd.DataFrame):\n    package_sizes = data['size']\n    plt.hist(package_sizes, bins=30, color='blue', alpha=0.7, label='Package Sizes')\n    plt.xlabel('Size')\n    plt.ylabel('Frequency')\n    plt.title('What is the distribution of package sizes in the flare-dependencies dataset?', wrap=True)\n    plt.legend()\n    return plt;\n\nchart = plot(data)"], ["import matplotlib.pyplot as plt\nimport pandas as pd\n\ndef plot(data: pd.DataFrame):\n    # Count the occurrences of each dependency type\n    dependency_counts = data['type'].value_counts()\n\n    # Create a bar chart of dependency types\n    ax = dependency_counts.plot(kind='bar', color='c', edgecolor='k')\n\n    # Set the title and labels\n    plt.title('What is the most common type of dependency in the flare-dependencies dataset?', wrap=True)\n    plt.xlabel('Dependency Types')\n    plt.ylabel('Frequency')\n\n    # Add a legend\n    ax.legend(['Dependency Types'])\n\n    return plt;\n\nchart = plot(data)"], ["import matplotlib.pyplot as plt\nimport pandas as pd\n\ndef plot(data: pd.DataFrame):\n    # Scatter plot of package size vs. number of dependencies\n    plt.scatter(data['package_size'], data['number_of_dependencies'])\n    plt.xlabel('Package Size')\n    plt.ylabel('Number of Dependencies')\n    plt.title('What is the relationship between package size and number of dependencies in the flare-dependencies dataset?', wrap=True)\n    return plt;\n\nchart = plot(data)"], ["import matplotlib.pyplot as plt\nimport pandas as pd\nfrom wordcloud import WordCloud\n\ndef plot(data: pd.DataFrame):\n    package_names = data['name'].tolist()\n    text = ' '.join(package_names)\n    wordcloud = WordCloud(background_color='white', colormap='viridis').generate(text)\n\n    plt.imshow(wordcloud, interpolation='bilinear')\n    plt.axis('off')\n    plt.title('What is the distribution of package names in the flare-dependencies dataset?', wrap=True)\n    return plt;\n\nchart = plot(data)"], ["import matplotlib.pyplot as plt\nimport pandas as pd\n\ndef plot(data: pd.DataFrame):\n    package_versions = data['version'].value_counts()\n    package_versions.plot(kind='bar', color='c', legend=True)\n    plt.title('What is the distribution of package versions in the flare-dependencies dataset?', wrap=True)\n    plt.xlabel('Package Versions')\n    plt.ylabel('Frequency')\n    plt.xticks(rotation=45)\n    plt.legend(['Package Versions'])\n    return plt;\n\nchart = plot(data)"]], "filename": "flare-dependencies.json", "chart": [[{"spec": null, "status": false, "raster": null, "code": "import matplotlib.pyplot as plt\nimport pandas as pd\n\ndef plot(data: pd.DataFrame):\n    package_sizes = data['size']\n    plt.hist(package_sizes, bins=30, color='blue', alpha=0.7, label='Package Sizes')\n    plt.xlabel('Size')\n    plt.ylabel('Frequency')\n    plt.title('What is the distribution of package sizes in the flare-dependencies dataset?', wrap=True)\n    plt.legend()\n    return plt;\n\nchart = plot(data)", "library": "matplotlib", "error": {"message": "'size'", "traceback": "Traceback (most recent call last):\n  File \"/home/victordibia/.local/lib/python3.9/site-packages/pandas/core/indexes/base.py\", line 3621, in get_loc\n    return self._engine.get_loc(casted_key)\n  File \"pandas/_libs/index.pyx\", line 136, in pandas._libs.index.IndexEngine.get_loc\n  File \"pandas/_libs/index.pyx\", line 163, in pandas._libs.index.IndexEngine.get_loc\n  File \"pandas/_libs/hashtable_class_helper.pxi\", line 5198, in pandas._libs.hashtable.PyObjectHashTable.get_item\n  File \"pandas/_libs/hashtable_class_helper.pxi\", line 5206, in pandas._libs.hashtable.PyObjectHashTable.get_item\nKeyError: 'size'\n\nThe above exception was the direct cause of the following exception:\n\nTraceback (most recent call last):\n  File \"/home/victordibia/projects/projectlida/lida/lib/lida/modules/executor.py\", line 144, in execute\n    exec(code, ex_locals)\n  File \"<string>\", line 13, in <module>\n  File \"<string>\", line 5, in plot\n  File \"/home/victordibia/.local/lib/python3.9/site-packages/pandas/core/frame.py\", line 3505, in __getitem__\n    indexer = self.columns.get_loc(key)\n  File \"/home/victordibia/.local/lib/python3.9/site-packages/pandas/core/indexes/base.py\", line 3623, in get_loc\n    raise KeyError(key) from err\nKeyError: 'size'\n"}}], [{"spec": null, "status": false, "raster": null, "code": "import matplotlib.pyplot as plt\nimport pandas as pd\n\ndef plot(data: pd.DataFrame):\n    # Count the occurrences of each dependency type\n    dependency_counts = data['type'].value_counts()\n\n    # Create a bar chart of dependency types\n    ax = dependency_counts.plot(kind='bar', color='c', edgecolor='k')\n\n    # Set the title and labels\n    plt.title('What is the most common type of dependency in the flare-dependencies dataset?', wrap=True)\n    plt.xlabel('Dependency Types')\n    plt.ylabel('Frequency')\n\n    # Add a legend\n    ax.legend(['Dependency Types'])\n\n    return plt;\n\nchart = plot(data)", "library": "matplotlib", "error": {"message": "'type'", "traceback": "Traceback (most recent call last):\n  File \"/home/victordibia/.local/lib/python3.9/site-packages/pandas/core/indexes/base.py\", line 3621, in get_loc\n    return self._engine.get_loc(casted_key)\n  File \"pandas/_libs/index.pyx\", line 136, in pandas._libs.index.IndexEngine.get_loc\n  File \"pandas/_libs/index.pyx\", line 163, in pandas._libs.index.IndexEngine.get_loc\n  File \"pandas/_libs/hashtable_class_helper.pxi\", line 5198, in pandas._libs.hashtable.PyObjectHashTable.get_item\n  File \"pandas/_libs/hashtable_class_helper.pxi\", line 5206, in pandas._libs.hashtable.PyObjectHashTable.get_item\nKeyError: 'type'\n\nThe above exception was the direct cause of the following exception:\n\nTraceback (most recent call last):\n  File \"/home/victordibia/projects/projectlida/lida/lib/lida/modules/executor.py\", line 144, in execute\n    exec(code, ex_locals)\n  File \"<string>\", line 21, in <module>\n  File \"<string>\", line 6, in plot\n  File \"/home/victordibia/.local/lib/python3.9/site-packages/pandas/core/frame.py\", line 3505, in __getitem__\n    indexer = self.columns.get_loc(key)\n  File \"/home/victordibia/.local/lib/python3.9/site-packages/pandas/core/indexes/base.py\", line 3623, in get_loc\n    raise KeyError(key) from err\nKeyError: 'type'\n"}}], [{"spec": null, "status": false, "raster": null, "code": "import matplotlib.pyplot as plt\nimport pandas as pd\n\ndef plot(data: pd.DataFrame):\n    # Scatter plot of package size vs. number of dependencies\n    plt.scatter(data['package_size'], data['number_of_dependencies'])\n    plt.xlabel('Package Size')\n    plt.ylabel('Number of Dependencies')\n    plt.title('What is the relationship between package size and number of dependencies in the flare-dependencies dataset?', wrap=True)\n    return plt;\n\nchart = plot(data)", "library": "matplotlib", "error": {"message": "'package_size'", "traceback": "Traceback (most recent call last):\n  File \"/home/victordibia/.local/lib/python3.9/site-packages/pandas/core/indexes/base.py\", line 3621, in get_loc\n    return self._engine.get_loc(casted_key)\n  File \"pandas/_libs/index.pyx\", line 136, in pandas._libs.index.IndexEngine.get_loc\n  File \"pandas/_libs/index.pyx\", line 163, in pandas._libs.index.IndexEngine.get_loc\n  File \"pandas/_libs/hashtable_class_helper.pxi\", line 5198, in pandas._libs.hashtable.PyObjectHashTable.get_item\n  File \"pandas/_libs/hashtable_class_helper.pxi\", line 5206, in pandas._libs.hashtable.PyObjectHashTable.get_item\nKeyError: 'package_size'\n\nThe above exception was the direct cause of the following exception:\n\nTraceback (most recent call last):\n  File \"/home/victordibia/projects/projectlida/lida/lib/lida/modules/executor.py\", line 144, in execute\n    exec(code, ex_locals)\n  File \"<string>\", line 12, in <module>\n  File \"<string>\", line 6, in plot\n  File \"/home/victordibia/.local/lib/python3.9/site-packages/pandas/core/frame.py\", line 3505, in __getitem__\n    indexer = self.columns.get_loc(key)\n  File \"/home/victordibia/.local/lib/python3.9/site-packages/pandas/core/indexes/base.py\", line 3623, in get_loc\n    raise KeyError(key) from err\nKeyError: 'package_size'\n"}}], [{"spec": null, "status": false, "raster": null, "code": "import matplotlib.pyplot as plt\nimport pandas as pd\nfrom wordcloud import WordCloud\n\ndef plot(data: pd.DataFrame):\n    package_names = data['name'].tolist()\n    text = ' '.join(package_names)\n    wordcloud = WordCloud(background_color='white', colormap='viridis').generate(text)\n\n    plt.imshow(wordcloud, interpolation='bilinear')\n    plt.axis('off')\n    plt.title('What is the distribution of package names in the flare-dependencies dataset?', wrap=True)\n    return plt;\n\nchart = plot(data)", "library": "matplotlib", "error": {"message": "'name'", "traceback": "Traceback (most recent call last):\n  File \"/home/victordibia/.local/lib/python3.9/site-packages/pandas/core/indexes/base.py\", line 3621, in get_loc\n    return self._engine.get_loc(casted_key)\n  File \"pandas/_libs/index.pyx\", line 136, in pandas._libs.index.IndexEngine.get_loc\n  File \"pandas/_libs/index.pyx\", line 163, in pandas._libs.index.IndexEngine.get_loc\n  File \"pandas/_libs/hashtable_class_helper.pxi\", line 5198, in pandas._libs.hashtable.PyObjectHashTable.get_item\n  File \"pandas/_libs/hashtable_class_helper.pxi\", line 5206, in pandas._libs.hashtable.PyObjectHashTable.get_item\nKeyError: 'name'\n\nThe above exception was the direct cause of the following exception:\n\nTraceback (most recent call last):\n  File \"/home/victordibia/projects/projectlida/lida/lib/lida/modules/executor.py\", line 144, in execute\n    exec(code, ex_locals)\n  File \"<string>\", line 15, in <module>\n  File \"<string>\", line 6, in plot\n  File \"/home/victordibia/.local/lib/python3.9/site-packages/pandas/core/frame.py\", line 3505, in __getitem__\n    indexer = self.columns.get_loc(key)\n  File \"/home/victordibia/.local/lib/python3.9/site-packages/pandas/core/indexes/base.py\", line 3623, in get_loc\n    raise KeyError(key) from err\nKeyError: 'name'\n"}}], [{"spec": null, "status": false, "raster": null, "code": "import matplotlib.pyplot as plt\nimport pandas as pd\n\ndef plot(data: pd.DataFrame):\n    package_versions = data['version'].value_counts()\n    package_versions.plot(kind='bar', color='c', legend=True)\n    plt.title('What is the distribution of package versions in the flare-dependencies dataset?', wrap=True)\n    plt.xlabel('Package Versions')\n    plt.ylabel('Frequency')\n    plt.xticks(rotation=45)\n    plt.legend(['Package Versions'])\n    return plt;\n\nchart = plot(data)", "library": "matplotlib", "error": {"message": "'version'", "traceback": "Traceback (most recent call last):\n  File \"/home/victordibia/.local/lib/python3.9/site-packages/pandas/core/indexes/base.py\", line 3621, in get_loc\n    return self._engine.get_loc(casted_key)\n  File \"pandas/_libs/index.pyx\", line 136, in pandas._libs.index.IndexEngine.get_loc\n  File \"pandas/_libs/index.pyx\", line 163, in pandas._libs.index.IndexEngine.get_loc\n  File \"pandas/_libs/hashtable_class_helper.pxi\", line 5198, in pandas._libs.hashtable.PyObjectHashTable.get_item\n  File \"pandas/_libs/hashtable_class_helper.pxi\", line 5206, in pandas._libs.hashtable.PyObjectHashTable.get_item\nKeyError: 'version'\n\nThe above exception was the direct cause of the following exception:\n\nTraceback (most recent call last):\n  File \"/home/victordibia/projects/projectlida/lida/lib/lida/modules/executor.py\", line 144, in execute\n    exec(code, ex_locals)\n  File \"<string>\", line 14, in <module>\n  File \"<string>\", line 5, in plot\n  File \"/home/victordibia/.local/lib/python3.9/site-packages/pandas/core/frame.py\", line 3505, in __getitem__\n    indexer = self.columns.get_loc(key)\n  File \"/home/victordibia/.local/lib/python3.9/site-packages/pandas/core/indexes/base.py\", line 3623, in get_loc\n    raise KeyError(key) from err\nKeyError: 'version'\n"}}]]}