{"summary": {"file_name": "la-riots.csv"}, "goals": [{"index": 0, "question": "What is the trend of the number of incidents reported during the LA riots?", "visualization": "Line chart of the number of incidents reported over time", "rationale": "This visualization will help us understand the overall pattern of the incidents reported during the LA riots and identify any spikes or dips in the number of incidents."}, {"index": 1, "question": "What is the distribution of the type of incidents reported during the LA riots?", "visualization": "Bar chart of the count of each type of incident", "rationale": "This visualization will help us understand the most common types of incidents reported during the LA riots and identify any outliers or unusual patterns."}, {"index": 2, "question": "What is the relationship between the number of incidents reported and the location of the incident?", "visualization": "Scatter plot of the number of incidents reported by location", "rationale": "This visualization will help us understand if there are any areas that were particularly affected by the LA riots and if there is any correlation between the location of the incident and the number of incidents reported."}, {"index": 3, "question": "What is the distribution of the severity of the incidents reported during the LA riots?", "visualization": "Histogram of the severity of the incidents reported", "rationale": "This visualization will help us understand the severity of the incidents reported during the LA riots and identify any outliers or unusual patterns."}, {"index": 4, "question": "What is the relationship between the number of incidents reported and the time of day?", "visualization": "Line chart of the number of incidents reported by time of day", "rationale": "This visualization will help us understand if there are any particular times of day when incidents were more likely to occur during the LA riots and if there is any correlation between the time of day and the number of incidents reported."}], "code": [["import matplotlib.pyplot as plt\nimport pandas as pd\n\ndef plot(data: pd.DataFrame):\n    data['date'] = pd.to_datetime(data['date'], errors='coerce')\n    data = data[pd.notna(data['date'])]\n    \n    data['count'] = 1\n    data_grouped = data.groupby(data['date'].dt.date).sum().reset_index()\n    \n    plt.plot(data_grouped['date'], data_grouped['count'], label='Incidents')\n    plt.xlabel('Date')\n    plt.ylabel('Number of Incidents')\n    plt.title('What is the trend of the number of incidents reported during the LA riots?', wrap=True)\n    plt.xticks(rotation=45)\n    plt.legend()\n    \n    return plt;\n\nchart = plot(data)"], ["import matplotlib.pyplot as plt\nimport pandas as pd\n\ndef plot(data: pd.DataFrame):\n    incident_counts = data['incident_type'].value_counts()\n    incident_counts.plot(kind='bar', color='blue', legend=True)\n    plt.title(\"What is the distribution of the type of incidents reported during the LA riots?\", wrap=True)\n    plt.xlabel(\"Incident Type\")\n    plt.ylabel(\"Count\")\n    plt.xticks(rotation=45)\n    return plt;\n\nchart = plot(data)"], ["import matplotlib.pyplot as plt\nimport pandas as pd\n\ndef plot(data: pd.DataFrame):\n    plt.scatter(data['location'], data['number_of_incidents'])\n    plt.xlabel('Location')\n    plt.ylabel('Number of Incidents')\n    plt.title('What is the relationship between the number of incidents reported and the location of the incident?', wrap=True)\n    plt.xticks(rotation=45)\n    plt.legend(['Incidents'])\n    return plt;\n\nchart = plot(data)"], ["import matplotlib.pyplot as plt\nimport pandas as pd\n\ndef plot(data: pd.DataFrame):\n    data['severity'].plot.hist(bins=10, alpha=0.5, color='blue', edgecolor='black')\n    plt.title(\"What is the distribution of the severity of the incidents reported during the LA riots?\", wrap=True)\n    plt.xlabel(\"Severity\")\n    plt.ylabel(\"Frequency\")\n    plt.axvline(data['severity'].median(), color='red', linestyle='dashed', linewidth=1, label=f\"Median: {data['severity'].median():.2f}\")\n    plt.legend()\n    return plt;\n\nchart = plot(data)"], ["import matplotlib.pyplot as plt\nimport pandas as pd\n\ndef plot(data: pd.DataFrame):\n    data['time_of_day'] = pd.to_datetime(data['time_of_day'], errors='coerce')\n    data = data[pd.notna(data['time_of_day'])]\n    data['hour'] = data['time_of_day'].dt.hour\n\n    incidents_by_hour = data.groupby('hour')['incident_id'].count()\n\n    plt.plot(incidents_by_hour.index, incidents_by_hour.values)\n    plt.xlabel('Time of Day (Hour)')\n    plt.ylabel('Number of Incidents Reported')\n    plt.title('What is the relationship between the number of incidents reported and the time of day?', wrap=True)\n    plt.xticks(range(0, 24))\n    plt.legend(['Incidents Reported'])\n\n    return plt;\n\nchart = plot(data)"]], "filename": "la-riots.csv", "chart": [[{"spec": null, "status": false, "raster": null, "code": "import matplotlib.pyplot as plt\nimport pandas as pd\n\ndef plot(data: pd.DataFrame):\n    data['date'] = pd.to_datetime(data['date'], errors='coerce')\n    data = data[pd.notna(data['date'])]\n    \n    data['count'] = 1\n    data_grouped = data.groupby(data['date'].dt.date).sum().reset_index()\n    \n    plt.plot(data_grouped['date'], data_grouped['count'], label='Incidents')\n    plt.xlabel('Date')\n    plt.ylabel('Number of Incidents')\n    plt.title('What is the trend of the number of incidents reported during the LA riots?', wrap=True)\n    plt.xticks(rotation=45)\n    plt.legend()\n    \n    return plt;\n\nchart = plot(data)", "library": "matplotlib", "error": {"message": "'date'", "traceback": "Traceback (most recent call last):\n  File \"/home/victordibia/.local/lib/python3.9/site-packages/pandas/core/indexes/base.py\", line 3621, in get_loc\n    return self._engine.get_loc(casted_key)\n  File \"pandas/_libs/index.pyx\", line 136, in pandas._libs.index.IndexEngine.get_loc\n  File \"pandas/_libs/index.pyx\", line 163, in pandas._libs.index.IndexEngine.get_loc\n  File \"pandas/_libs/hashtable_class_helper.pxi\", line 5198, in pandas._libs.hashtable.PyObjectHashTable.get_item\n  File \"pandas/_libs/hashtable_class_helper.pxi\", line 5206, in pandas._libs.hashtable.PyObjectHashTable.get_item\nKeyError: 'date'\n\nThe above exception was the direct cause of the following exception:\n\nTraceback (most recent call last):\n  File \"/home/victordibia/projects/projectlida/lida/lib/lida/modules/executor.py\", line 144, in execute\n    exec(code, ex_locals)\n  File \"<string>\", line 20, in <module>\n  File \"<string>\", line 5, in plot\n  File \"/home/victordibia/.local/lib/python3.9/site-packages/pandas/core/frame.py\", line 3505, in __getitem__\n    indexer = self.columns.get_loc(key)\n  File \"/home/victordibia/.local/lib/python3.9/site-packages/pandas/core/indexes/base.py\", line 3623, in get_loc\n    raise KeyError(key) from err\nKeyError: 'date'\n"}}], [{"spec": null, "status": false, "raster": null, "code": "import matplotlib.pyplot as plt\nimport pandas as pd\n\ndef plot(data: pd.DataFrame):\n    incident_counts = data['incident_type'].value_counts()\n    incident_counts.plot(kind='bar', color='blue', legend=True)\n    plt.title(\"What is the distribution of the type of incidents reported during the LA riots?\", wrap=True)\n    plt.xlabel(\"Incident Type\")\n    plt.ylabel(\"Count\")\n    plt.xticks(rotation=45)\n    return plt;\n\nchart = plot(data)", "library": "matplotlib", "error": {"message": "'incident_type'", "traceback": "Traceback (most recent call last):\n  File \"/home/victordibia/.local/lib/python3.9/site-packages/pandas/core/indexes/base.py\", line 3621, in get_loc\n    return self._engine.get_loc(casted_key)\n  File \"pandas/_libs/index.pyx\", line 136, in pandas._libs.index.IndexEngine.get_loc\n  File \"pandas/_libs/index.pyx\", line 163, in pandas._libs.index.IndexEngine.get_loc\n  File \"pandas/_libs/hashtable_class_helper.pxi\", line 5198, in pandas._libs.hashtable.PyObjectHashTable.get_item\n  File \"pandas/_libs/hashtable_class_helper.pxi\", line 5206, in pandas._libs.hashtable.PyObjectHashTable.get_item\nKeyError: 'incident_type'\n\nThe above exception was the direct cause of the following exception:\n\nTraceback (most recent call last):\n  File \"/home/victordibia/projects/projectlida/lida/lib/lida/modules/executor.py\", line 144, in execute\n    exec(code, ex_locals)\n  File \"<string>\", line 13, in <module>\n  File \"<string>\", line 5, in plot\n  File \"/home/victordibia/.local/lib/python3.9/site-packages/pandas/core/frame.py\", line 3505, in __getitem__\n    indexer = self.columns.get_loc(key)\n  File \"/home/victordibia/.local/lib/python3.9/site-packages/pandas/core/indexes/base.py\", line 3623, in get_loc\n    raise KeyError(key) from err\nKeyError: 'incident_type'\n"}}], [{"spec": null, "status": false, "raster": null, "code": "import matplotlib.pyplot as plt\nimport pandas as pd\n\ndef plot(data: pd.DataFrame):\n    plt.scatter(data['location'], data['number_of_incidents'])\n    plt.xlabel('Location')\n    plt.ylabel('Number of Incidents')\n    plt.title('What is the relationship between the number of incidents reported and the location of the incident?', wrap=True)\n    plt.xticks(rotation=45)\n    plt.legend(['Incidents'])\n    return plt;\n\nchart = plot(data)", "library": "matplotlib", "error": {"message": "'location'", "traceback": "Traceback (most recent call last):\n  File \"/home/victordibia/.local/lib/python3.9/site-packages/pandas/core/indexes/base.py\", line 3621, in get_loc\n    return self._engine.get_loc(casted_key)\n  File \"pandas/_libs/index.pyx\", line 136, in pandas._libs.index.IndexEngine.get_loc\n  File \"pandas/_libs/index.pyx\", line 163, in pandas._libs.index.IndexEngine.get_loc\n  File \"pandas/_libs/hashtable_class_helper.pxi\", line 5198, in pandas._libs.hashtable.PyObjectHashTable.get_item\n  File \"pandas/_libs/hashtable_class_helper.pxi\", line 5206, in pandas._libs.hashtable.PyObjectHashTable.get_item\nKeyError: 'location'\n\nThe above exception was the direct cause of the following exception:\n\nTraceback (most recent call last):\n  File \"/home/victordibia/projects/projectlida/lida/lib/lida/modules/executor.py\", line 144, in execute\n    exec(code, ex_locals)\n  File \"<string>\", line 13, in <module>\n  File \"<string>\", line 5, in plot\n  File \"/home/victordibia/.local/lib/python3.9/site-packages/pandas/core/frame.py\", line 3505, in __getitem__\n    indexer = self.columns.get_loc(key)\n  File \"/home/victordibia/.local/lib/python3.9/site-packages/pandas/core/indexes/base.py\", line 3623, in get_loc\n    raise KeyError(key) from err\nKeyError: 'location'\n"}}], [{"spec": null, "status": false, "raster": null, "code": "import matplotlib.pyplot as plt\nimport pandas as pd\n\ndef plot(data: pd.DataFrame):\n    data['severity'].plot.hist(bins=10, alpha=0.5, color='blue', edgecolor='black')\n    plt.title(\"What is the distribution of the severity of the incidents reported during the LA riots?\", wrap=True)\n    plt.xlabel(\"Severity\")\n    plt.ylabel(\"Frequency\")\n    plt.axvline(data['severity'].median(), color='red', linestyle='dashed', linewidth=1, label=f\"Median: {data['severity'].median():.2f}\")\n    plt.legend()\n    return plt;\n\nchart = plot(data)", "library": "matplotlib", "error": {"message": "'severity'", "traceback": "Traceback (most recent call last):\n  File \"/home/victordibia/.local/lib/python3.9/site-packages/pandas/core/indexes/base.py\", line 3621, in get_loc\n    return self._engine.get_loc(casted_key)\n  File \"pandas/_libs/index.pyx\", line 136, in pandas._libs.index.IndexEngine.get_loc\n  File \"pandas/_libs/index.pyx\", line 163, in pandas._libs.index.IndexEngine.get_loc\n  File \"pandas/_libs/hashtable_class_helper.pxi\", line 5198, in pandas._libs.hashtable.PyObjectHashTable.get_item\n  File \"pandas/_libs/hashtable_class_helper.pxi\", line 5206, in pandas._libs.hashtable.PyObjectHashTable.get_item\nKeyError: 'severity'\n\nThe above exception was the direct cause of the following exception:\n\nTraceback (most recent call last):\n  File \"/home/victordibia/projects/projectlida/lida/lib/lida/modules/executor.py\", line 144, in execute\n    exec(code, ex_locals)\n  File \"<string>\", line 13, in <module>\n  File \"<string>\", line 5, in plot\n  File \"/home/victordibia/.local/lib/python3.9/site-packages/pandas/core/frame.py\", line 3505, in __getitem__\n    indexer = self.columns.get_loc(key)\n  File \"/home/victordibia/.local/lib/python3.9/site-packages/pandas/core/indexes/base.py\", line 3623, in get_loc\n    raise KeyError(key) from err\nKeyError: 'severity'\n"}}], [{"spec": null, "status": false, "raster": null, "code": "import matplotlib.pyplot as plt\nimport pandas as pd\n\ndef plot(data: pd.DataFrame):\n    data['time_of_day'] = pd.to_datetime(data['time_of_day'], errors='coerce')\n    data = data[pd.notna(data['time_of_day'])]\n    data['hour'] = data['time_of_day'].dt.hour\n\n    incidents_by_hour = data.groupby('hour')['incident_id'].count()\n\n    plt.plot(incidents_by_hour.index, incidents_by_hour.values)\n    plt.xlabel('Time of Day (Hour)')\n    plt.ylabel('Number of Incidents Reported')\n    plt.title('What is the relationship between the number of incidents reported and the time of day?', wrap=True)\n    plt.xticks(range(0, 24))\n    plt.legend(['Incidents Reported'])\n\n    return plt;\n\nchart = plot(data)", "library": "matplotlib", "error": {"message": "'time_of_day'", "traceback": "Traceback (most recent call last):\n  File \"/home/victordibia/.local/lib/python3.9/site-packages/pandas/core/indexes/base.py\", line 3621, in get_loc\n    return self._engine.get_loc(casted_key)\n  File \"pandas/_libs/index.pyx\", line 136, in pandas._libs.index.IndexEngine.get_loc\n  File \"pandas/_libs/index.pyx\", line 163, in pandas._libs.index.IndexEngine.get_loc\n  File \"pandas/_libs/hashtable_class_helper.pxi\", line 5198, in pandas._libs.hashtable.PyObjectHashTable.get_item\n  File \"pandas/_libs/hashtable_class_helper.pxi\", line 5206, in pandas._libs.hashtable.PyObjectHashTable.get_item\nKeyError: 'time_of_day'\n\nThe above exception was the direct cause of the following exception:\n\nTraceback (most recent call last):\n  File \"/home/victordibia/projects/projectlida/lida/lib/lida/modules/executor.py\", line 144, in execute\n    exec(code, ex_locals)\n  File \"<string>\", line 20, in <module>\n  File \"<string>\", line 5, in plot\n  File \"/home/victordibia/.local/lib/python3.9/site-packages/pandas/core/frame.py\", line 3505, in __getitem__\n    indexer = self.columns.get_loc(key)\n  File \"/home/victordibia/.local/lib/python3.9/site-packages/pandas/core/indexes/base.py\", line 3623, in get_loc\n    raise KeyError(key) from err\nKeyError: 'time_of_day'\n"}}]]}