{"summary": {"file_name": "iowa-electricity.csv"}, "goals": [{"index": 0, "question": "What is the trend of electricity consumption in Iowa over the years?", "visualization": "Line chart of electricity consumption over time", "rationale": "This visualization will help us understand if there is an increase or decrease in electricity consumption in Iowa over the years."}, {"index": 1, "question": "What is the distribution of residential electricity consumption in Iowa?", "visualization": "Histogram of residential electricity consumption", "rationale": "This visualization will help us understand the range and frequency of residential electricity consumption in Iowa."}, {"index": 2, "question": "What is the correlation between commercial and industrial electricity consumption in Iowa?", "visualization": "Scatter plot of commercial and industrial electricity consumption", "rationale": "This visualization will help us understand if there is a positive or negative correlation between commercial and industrial electricity consumption in Iowa."}, {"index": 3, "question": "What is the average electricity consumption per capita in Iowa?", "visualization": "Bar chart of electricity consumption per capita", "rationale": "This visualization will help us understand the average electricity consumption per person in Iowa."}, {"index": 4, "question": "What is the distribution of electricity rates in Iowa?", "visualization": "Box plot of electricity rates", "rationale": "This visualization will help us understand the range and distribution of electricity rates in Iowa."}], "code": [["import matplotlib.pyplot as plt\nimport pandas as pd\n\ndef plot(data: pd.DataFrame):\n    data['Year'] = pd.to_datetime(data['Year'], errors='coerce')\n    data = data[pd.notna(data['Year'])]\n    data['Year'] = data['Year'].dt.year\n\n    plt.plot(data['Year'], data['Electricity Consumption'], label='Electricity Consumption')\n    plt.xlabel('Year')\n    plt.ylabel('Electricity Consumption')\n    plt.title('What is the trend of electricity consumption in Iowa over the years?', wrap=True)\n    plt.legend()\n    return plt;\n\nchart = plot(data)"], ["import matplotlib.pyplot as plt\nimport pandas as pd\n\ndef plot(data: pd.DataFrame):\n    data['residential_electricity_consumption'] = data['residential_electricity_consumption'].astype(float)\n    plt.hist(data['residential_electricity_consumption'], bins=30, color='blue', alpha=0.7, label='Residential Electricity Consumption')\n    plt.xlabel('Residential Electricity Consumption')\n    plt.ylabel('Frequency')\n    plt.title('What is the distribution of residential electricity consumption in Iowa?', wrap=True)\n    plt.legend()\n    return plt;\n\nchart = plot(data)"], ["import matplotlib.pyplot as plt\nimport pandas as pd\n\ndef plot(data: pd.DataFrame):\n    plt.scatter(data['commercial'], data['industrial'])\n    plt.xlabel('Commercial Electricity Consumption')\n    plt.ylabel('Industrial Electricity Consumption')\n    plt.title('What is the correlation between commercial and industrial electricity consumption in Iowa?', wrap=True)\n    return plt;\n\nchart = plot(data)"], ["import matplotlib.pyplot as plt\nimport pandas as pd\n\ndef plot(data: pd.DataFrame):\n    data['Year'] = pd.to_datetime(data['Year'], errors='coerce')\n    data = data[pd.notna(data['Year'])]\n    data['Year'] = data['Year'].dt.year\n\n    avg_electricity_per_capita = data.groupby('Year')['Per capita'].mean()\n\n    plt.bar(avg_electricity_per_capita.index, avg_electricity_per_capita.values)\n    plt.xlabel('Year')\n    plt.ylabel('Average Electricity Consumption per Capita')\n    plt.title('What is the average electricity consumption per capita in Iowa?', wrap=True)\n    plt.xticks(rotation=45)\n    \n    return plt;\n\nchart = plot(data)"], ["import matplotlib.pyplot as plt\nimport pandas as pd\n\ndef plot(data: pd.DataFrame):\n    fig, ax = plt.subplots()\n    ax.boxplot(data['electricity_rates'])\n    ax.set_title('What is the distribution of electricity rates in Iowa?')\n    ax.set_ylabel('Electricity Rates')\n    ax.set_xticklabels(['Iowa'])\n    plt.legend(['Electricity Rates'])\n    return plt;\n\nchart = plot(data)"]], "filename": "iowa-electricity.csv", "chart": [[{"spec": null, "status": false, "raster": null, "code": "import matplotlib.pyplot as plt\nimport pandas as pd\n\ndef plot(data: pd.DataFrame):\n    data['Year'] = pd.to_datetime(data['Year'], errors='coerce')\n    data = data[pd.notna(data['Year'])]\n    data['Year'] = data['Year'].dt.year\n\n    plt.plot(data['Year'], data['Electricity Consumption'], label='Electricity Consumption')\n    plt.xlabel('Year')\n    plt.ylabel('Electricity Consumption')\n    plt.title('What is the trend of electricity consumption in Iowa over the years?', wrap=True)\n    plt.legend()\n    return plt;\n\nchart = plot(data)", "library": "matplotlib", "error": {"message": "'Year'", "traceback": "Traceback (most recent call last):\n  File \"/home/victordibia/.local/lib/python3.9/site-packages/pandas/core/indexes/base.py\", line 3621, in get_loc\n    return self._engine.get_loc(casted_key)\n  File \"pandas/_libs/index.pyx\", line 136, in pandas._libs.index.IndexEngine.get_loc\n  File \"pandas/_libs/index.pyx\", line 163, in pandas._libs.index.IndexEngine.get_loc\n  File \"pandas/_libs/hashtable_class_helper.pxi\", line 5198, in pandas._libs.hashtable.PyObjectHashTable.get_item\n  File \"pandas/_libs/hashtable_class_helper.pxi\", line 5206, in pandas._libs.hashtable.PyObjectHashTable.get_item\nKeyError: 'Year'\n\nThe above exception was the direct cause of the following exception:\n\nTraceback (most recent call last):\n  File \"/home/victordibia/projects/projectlida/lida/lib/lida/modules/executor.py\", line 144, in execute\n    exec(code, ex_locals)\n  File \"<string>\", line 16, in <module>\n  File \"<string>\", line 5, in plot\n  File \"/home/victordibia/.local/lib/python3.9/site-packages/pandas/core/frame.py\", line 3505, in __getitem__\n    indexer = self.columns.get_loc(key)\n  File \"/home/victordibia/.local/lib/python3.9/site-packages/pandas/core/indexes/base.py\", line 3623, in get_loc\n    raise KeyError(key) from err\nKeyError: 'Year'\n"}}], [{"spec": null, "status": false, "raster": null, "code": "import matplotlib.pyplot as plt\nimport pandas as pd\n\ndef plot(data: pd.DataFrame):\n    data['residential_electricity_consumption'] = data['residential_electricity_consumption'].astype(float)\n    plt.hist(data['residential_electricity_consumption'], bins=30, color='blue', alpha=0.7, label='Residential Electricity Consumption')\n    plt.xlabel('Residential Electricity Consumption')\n    plt.ylabel('Frequency')\n    plt.title('What is the distribution of residential electricity consumption in Iowa?', wrap=True)\n    plt.legend()\n    return plt;\n\nchart = plot(data)", "library": "matplotlib", "error": {"message": "'residential_electricity_consumption'", "traceback": "Traceback (most recent call last):\n  File \"/home/victordibia/.local/lib/python3.9/site-packages/pandas/core/indexes/base.py\", line 3621, in get_loc\n    return self._engine.get_loc(casted_key)\n  File \"pandas/_libs/index.pyx\", line 136, in pandas._libs.index.IndexEngine.get_loc\n  File \"pandas/_libs/index.pyx\", line 163, in pandas._libs.index.IndexEngine.get_loc\n  File \"pandas/_libs/hashtable_class_helper.pxi\", line 5198, in pandas._libs.hashtable.PyObjectHashTable.get_item\n  File \"pandas/_libs/hashtable_class_helper.pxi\", line 5206, in pandas._libs.hashtable.PyObjectHashTable.get_item\nKeyError: 'residential_electricity_consumption'\n\nThe above exception was the direct cause of the following exception:\n\nTraceback (most recent call last):\n  File \"/home/victordibia/projects/projectlida/lida/lib/lida/modules/executor.py\", line 144, in execute\n    exec(code, ex_locals)\n  File \"<string>\", line 13, in <module>\n  File \"<string>\", line 5, in plot\n  File \"/home/victordibia/.local/lib/python3.9/site-packages/pandas/core/frame.py\", line 3505, in __getitem__\n    indexer = self.columns.get_loc(key)\n  File \"/home/victordibia/.local/lib/python3.9/site-packages/pandas/core/indexes/base.py\", line 3623, in get_loc\n    raise KeyError(key) from err\nKeyError: 'residential_electricity_consumption'\n"}}], [{"spec": null, "status": false, "raster": null, "code": "import matplotlib.pyplot as plt\nimport pandas as pd\n\ndef plot(data: pd.DataFrame):\n    plt.scatter(data['commercial'], data['industrial'])\n    plt.xlabel('Commercial Electricity Consumption')\n    plt.ylabel('Industrial Electricity Consumption')\n    plt.title('What is the correlation between commercial and industrial electricity consumption in Iowa?', wrap=True)\n    return plt;\n\nchart = plot(data)", "library": "matplotlib", "error": {"message": "'commercial'", "traceback": "Traceback (most recent call last):\n  File \"/home/victordibia/.local/lib/python3.9/site-packages/pandas/core/indexes/base.py\", line 3621, in get_loc\n    return self._engine.get_loc(casted_key)\n  File \"pandas/_libs/index.pyx\", line 136, in pandas._libs.index.IndexEngine.get_loc\n  File \"pandas/_libs/index.pyx\", line 163, in pandas._libs.index.IndexEngine.get_loc\n  File \"pandas/_libs/hashtable_class_helper.pxi\", line 5198, in pandas._libs.hashtable.PyObjectHashTable.get_item\n  File \"pandas/_libs/hashtable_class_helper.pxi\", line 5206, in pandas._libs.hashtable.PyObjectHashTable.get_item\nKeyError: 'commercial'\n\nThe above exception was the direct cause of the following exception:\n\nTraceback (most recent call last):\n  File \"/home/victordibia/projects/projectlida/lida/lib/lida/modules/executor.py\", line 144, in execute\n    exec(code, ex_locals)\n  File \"<string>\", line 11, in <module>\n  File \"<string>\", line 5, in plot\n  File \"/home/victordibia/.local/lib/python3.9/site-packages/pandas/core/frame.py\", line 3505, in __getitem__\n    indexer = self.columns.get_loc(key)\n  File \"/home/victordibia/.local/lib/python3.9/site-packages/pandas/core/indexes/base.py\", line 3623, in get_loc\n    raise KeyError(key) from err\nKeyError: 'commercial'\n"}}], [{"spec": null, "status": false, "raster": null, "code": "import matplotlib.pyplot as plt\nimport pandas as pd\n\ndef plot(data: pd.DataFrame):\n    data['Year'] = pd.to_datetime(data['Year'], errors='coerce')\n    data = data[pd.notna(data['Year'])]\n    data['Year'] = data['Year'].dt.year\n\n    avg_electricity_per_capita = data.groupby('Year')['Per capita'].mean()\n\n    plt.bar(avg_electricity_per_capita.index, avg_electricity_per_capita.values)\n    plt.xlabel('Year')\n    plt.ylabel('Average Electricity Consumption per Capita')\n    plt.title('What is the average electricity consumption per capita in Iowa?', wrap=True)\n    plt.xticks(rotation=45)\n    \n    return plt;\n\nchart = plot(data)", "library": "matplotlib", "error": {"message": "'Year'", "traceback": "Traceback (most recent call last):\n  File \"/home/victordibia/.local/lib/python3.9/site-packages/pandas/core/indexes/base.py\", line 3621, in get_loc\n    return self._engine.get_loc(casted_key)\n  File \"pandas/_libs/index.pyx\", line 136, in pandas._libs.index.IndexEngine.get_loc\n  File \"pandas/_libs/index.pyx\", line 163, in pandas._libs.index.IndexEngine.get_loc\n  File \"pandas/_libs/hashtable_class_helper.pxi\", line 5198, in pandas._libs.hashtable.PyObjectHashTable.get_item\n  File \"pandas/_libs/hashtable_class_helper.pxi\", line 5206, in pandas._libs.hashtable.PyObjectHashTable.get_item\nKeyError: 'Year'\n\nThe above exception was the direct cause of the following exception:\n\nTraceback (most recent call last):\n  File \"/home/victordibia/projects/projectlida/lida/lib/lida/modules/executor.py\", line 144, in execute\n    exec(code, ex_locals)\n  File \"<string>\", line 19, in <module>\n  File \"<string>\", line 5, in plot\n  File \"/home/victordibia/.local/lib/python3.9/site-packages/pandas/core/frame.py\", line 3505, in __getitem__\n    indexer = self.columns.get_loc(key)\n  File \"/home/victordibia/.local/lib/python3.9/site-packages/pandas/core/indexes/base.py\", line 3623, in get_loc\n    raise KeyError(key) from err\nKeyError: 'Year'\n"}}], [{"spec": null, "status": false, "raster": null, "code": "import matplotlib.pyplot as plt\nimport pandas as pd\n\ndef plot(data: pd.DataFrame):\n    fig, ax = plt.subplots()\n    ax.boxplot(data['electricity_rates'])\n    ax.set_title('What is the distribution of electricity rates in Iowa?')\n    ax.set_ylabel('Electricity Rates')\n    ax.set_xticklabels(['Iowa'])\n    plt.legend(['Electricity Rates'])\n    return plt;\n\nchart = plot(data)", "library": "matplotlib", "error": {"message": "'electricity_rates'", "traceback": "Traceback (most recent call last):\n  File \"/home/victordibia/.local/lib/python3.9/site-packages/pandas/core/indexes/base.py\", line 3621, in get_loc\n    return self._engine.get_loc(casted_key)\n  File \"pandas/_libs/index.pyx\", line 136, in pandas._libs.index.IndexEngine.get_loc\n  File \"pandas/_libs/index.pyx\", line 163, in pandas._libs.index.IndexEngine.get_loc\n  File \"pandas/_libs/hashtable_class_helper.pxi\", line 5198, in pandas._libs.hashtable.PyObjectHashTable.get_item\n  File \"pandas/_libs/hashtable_class_helper.pxi\", line 5206, in pandas._libs.hashtable.PyObjectHashTable.get_item\nKeyError: 'electricity_rates'\n\nThe above exception was the direct cause of the following exception:\n\nTraceback (most recent call last):\n  File \"/home/victordibia/projects/projectlida/lida/lib/lida/modules/executor.py\", line 144, in execute\n    exec(code, ex_locals)\n  File \"<string>\", line 13, in <module>\n  File \"<string>\", line 6, in plot\n  File \"/home/victordibia/.local/lib/python3.9/site-packages/pandas/core/frame.py\", line 3505, in __getitem__\n    indexer = self.columns.get_loc(key)\n  File \"/home/victordibia/.local/lib/python3.9/site-packages/pandas/core/indexes/base.py\", line 3623, in get_loc\n    raise KeyError(key) from err\nKeyError: 'electricity_rates'\n"}}]]}