{"summary": {"file_name": "sp500-2000.csv"}, "goals": [{"index": 0, "question": "What is the distribution of daily returns for the S&P 500 index?", "visualization": "Histogram of daily returns", "rationale": "This visualization can help us understand the volatility of the S&P 500 index and identify any potential outliers."}, {"index": 1, "question": "What is the correlation between the S&P 500 index and the NASDAQ index?", "visualization": "Scatter plot of S&P 500 index vs NASDAQ index", "rationale": "This visualization can help us understand the relationship between the two indices and identify any potential patterns or trends."}, {"index": 2, "question": "What is the trend of the S&P 500 index over time?", "visualization": "Line chart of S&P 500 index over time", "rationale": "This visualization can help us understand the overall performance of the S&P 500 index and identify any potential long-term trends."}, {"index": 3, "question": "What is the distribution of trading volumes for the S&P 500 index?", "visualization": "Histogram of trading volumes", "rationale": "This visualization can help us understand the liquidity of the S&P 500 index and identify any potential outliers."}, {"index": 4, "question": "What is the distribution of daily changes in the S&P 500 index?", "visualization": "Box plot of daily changes", "rationale": "This visualization can help us understand the variability of daily changes in the S&P 500 index and identify any potential outliers or trends."}], "code": [["import matplotlib.pyplot as plt\nimport pandas as pd\n\ndef plot(data: pd.DataFrame):\n    data['Date'] = pd.to_datetime(data['Date'], errors='coerce')\n    data = data[pd.notna(data['Date'])]\n    data['Daily_Return'] = data['Close'].pct_change()\n    data = data.dropna()\n\n    plt.hist(data['Daily_Return'], bins=50, color='blue', alpha=0.7, label='Daily Returns')\n    plt.axvline(data['Daily_Return'].median(), color='red', linestyle='dashed', linewidth=2, label=f\"Median: {data['Daily_Return'].median():.2f}\")\n    plt.xlabel('Daily Returns')\n    plt.ylabel('Frequency')\n    plt.title('What is the distribution of daily returns for the S&P 500 index?', wrap=True)\n    plt.legend()\n    return plt;\n\nchart = plot(data)"], ["import matplotlib.pyplot as plt\nimport pandas as pd\n\ndef plot(data: pd.DataFrame):\n    data['Date'] = pd.to_datetime(data['Date'], errors='coerce')\n    data = data[pd.notna(data['Date'])]\n\n    plt.scatter(data['S&P 500'], data['NASDAQ'], label='S&P 500 vs NASDAQ')\n    plt.xlabel('S&P 500 Index')\n    plt.ylabel('NASDAQ Index')\n    plt.title('What is the correlation between the S&P 500 index and the NASDAQ index?', wrap=True)\n    plt.legend()\n    return plt;\n\nchart = plot(data)"], ["import matplotlib.pyplot as plt\nimport pandas as pd\n\ndef plot(data: pd.DataFrame):\n    data['Date'] = pd.to_datetime(data['Date'], errors='coerce')\n    data = data[pd.notna(data['Date'])]\n    \n    plt.plot(data['Date'], data['Close'], label='S&P 500 Index')\n    plt.xlabel('Date')\n    plt.ylabel('Close')\n    plt.title('What is the trend of the S&P 500 index over time?', wrap=True)\n    plt.legend()\n    plt.xticks(rotation=45)\n    \n    return plt;\n\nchart = plot(data)"], ["import matplotlib.pyplot as plt\nimport pandas as pd\n\ndef plot(data: pd.DataFrame):\n    data['Date'] = pd.to_datetime(data['Date'], errors='coerce')\n    data = data[pd.notna(data['Date'])]\n    \n    plt.hist(data['Volume'], bins=50, color='blue', alpha=0.7)\n    plt.axvline(data['Volume'].median(), color='red', linestyle='dashed', linewidth=2, label=f\"Median: {data['Volume'].median():.2f}\")\n    plt.xlabel('Trading Volume')\n    plt.ylabel('Frequency')\n    plt.title('What is the distribution of trading volumes for the S&P 500 index?', wrap=True)\n    plt.legend()\n    return plt;\n\nchart = plot(data)"], ["import matplotlib.pyplot as plt\nimport pandas as pd\n\ndef plot(data: pd.DataFrame):\n    data['Date'] = pd.to_datetime(data['Date'], errors='coerce')\n    data = data[pd.notna(data['Date'])]\n    data['Daily_Change'] = data['Close'].diff()\n    \n    fig, ax = plt.subplots()\n    ax.boxplot(data['Daily_Change'].dropna(), vert=False)\n    ax.set_xlabel('Daily Change')\n    ax.set_yticklabels(['S&P 500'])\n    plt.title('What is the distribution of daily changes in the S&P 500 index?', wrap=True)\n    \n    return plt;\n\nchart = plot(data)"]], "filename": "sp500-2000.csv", "chart": [[{"spec": null, "status": false, "raster": null, "code": "import matplotlib.pyplot as plt\nimport pandas as pd\n\ndef plot(data: pd.DataFrame):\n    data['Date'] = pd.to_datetime(data['Date'], errors='coerce')\n    data = data[pd.notna(data['Date'])]\n    data['Daily_Return'] = data['Close'].pct_change()\n    data = data.dropna()\n\n    plt.hist(data['Daily_Return'], bins=50, color='blue', alpha=0.7, label='Daily Returns')\n    plt.axvline(data['Daily_Return'].median(), color='red', linestyle='dashed', linewidth=2, label=f\"Median: {data['Daily_Return'].median():.2f}\")\n    plt.xlabel('Daily Returns')\n    plt.ylabel('Frequency')\n    plt.title('What is the distribution of daily returns for the S&P 500 index?', wrap=True)\n    plt.legend()\n    return plt;\n\nchart = plot(data)", "library": "matplotlib", "error": {"message": "'Date'", "traceback": "Traceback (most recent call last):\n  File \"/home/victordibia/.local/lib/python3.9/site-packages/pandas/core/indexes/base.py\", line 3621, in get_loc\n    return self._engine.get_loc(casted_key)\n  File \"pandas/_libs/index.pyx\", line 136, in pandas._libs.index.IndexEngine.get_loc\n  File \"pandas/_libs/index.pyx\", line 163, in pandas._libs.index.IndexEngine.get_loc\n  File \"pandas/_libs/hashtable_class_helper.pxi\", line 5198, in pandas._libs.hashtable.PyObjectHashTable.get_item\n  File \"pandas/_libs/hashtable_class_helper.pxi\", line 5206, in pandas._libs.hashtable.PyObjectHashTable.get_item\nKeyError: 'Date'\n\nThe above exception was the direct cause of the following exception:\n\nTraceback (most recent call last):\n  File \"/home/victordibia/projects/projectlida/lida/lib/lida/modules/executor.py\", line 144, in execute\n    exec(code, ex_locals)\n  File \"<string>\", line 18, in <module>\n  File \"<string>\", line 5, in plot\n  File \"/home/victordibia/.local/lib/python3.9/site-packages/pandas/core/frame.py\", line 3505, in __getitem__\n    indexer = self.columns.get_loc(key)\n  File \"/home/victordibia/.local/lib/python3.9/site-packages/pandas/core/indexes/base.py\", line 3623, in get_loc\n    raise KeyError(key) from err\nKeyError: 'Date'\n"}}], [{"spec": null, "status": false, "raster": null, "code": "import matplotlib.pyplot as plt\nimport pandas as pd\n\ndef plot(data: pd.DataFrame):\n    data['Date'] = pd.to_datetime(data['Date'], errors='coerce')\n    data = data[pd.notna(data['Date'])]\n\n    plt.scatter(data['S&P 500'], data['NASDAQ'], label='S&P 500 vs NASDAQ')\n    plt.xlabel('S&P 500 Index')\n    plt.ylabel('NASDAQ Index')\n    plt.title('What is the correlation between the S&P 500 index and the NASDAQ index?', wrap=True)\n    plt.legend()\n    return plt;\n\nchart = plot(data)", "library": "matplotlib", "error": {"message": "'Date'", "traceback": "Traceback (most recent call last):\n  File \"/home/victordibia/.local/lib/python3.9/site-packages/pandas/core/indexes/base.py\", line 3621, in get_loc\n    return self._engine.get_loc(casted_key)\n  File \"pandas/_libs/index.pyx\", line 136, in pandas._libs.index.IndexEngine.get_loc\n  File \"pandas/_libs/index.pyx\", line 163, in pandas._libs.index.IndexEngine.get_loc\n  File \"pandas/_libs/hashtable_class_helper.pxi\", line 5198, in pandas._libs.hashtable.PyObjectHashTable.get_item\n  File \"pandas/_libs/hashtable_class_helper.pxi\", line 5206, in pandas._libs.hashtable.PyObjectHashTable.get_item\nKeyError: 'Date'\n\nThe above exception was the direct cause of the following exception:\n\nTraceback (most recent call last):\n  File \"/home/victordibia/projects/projectlida/lida/lib/lida/modules/executor.py\", line 144, in execute\n    exec(code, ex_locals)\n  File \"<string>\", line 15, in <module>\n  File \"<string>\", line 5, in plot\n  File \"/home/victordibia/.local/lib/python3.9/site-packages/pandas/core/frame.py\", line 3505, in __getitem__\n    indexer = self.columns.get_loc(key)\n  File \"/home/victordibia/.local/lib/python3.9/site-packages/pandas/core/indexes/base.py\", line 3623, in get_loc\n    raise KeyError(key) from err\nKeyError: 'Date'\n"}}], [{"spec": null, "status": false, "raster": null, "code": "import matplotlib.pyplot as plt\nimport pandas as pd\n\ndef plot(data: pd.DataFrame):\n    data['Date'] = pd.to_datetime(data['Date'], errors='coerce')\n    data = data[pd.notna(data['Date'])]\n    \n    plt.plot(data['Date'], data['Close'], label='S&P 500 Index')\n    plt.xlabel('Date')\n    plt.ylabel('Close')\n    plt.title('What is the trend of the S&P 500 index over time?', wrap=True)\n    plt.legend()\n    plt.xticks(rotation=45)\n    \n    return plt;\n\nchart = plot(data)", "library": "matplotlib", "error": {"message": "'Date'", "traceback": "Traceback (most recent call last):\n  File \"/home/victordibia/.local/lib/python3.9/site-packages/pandas/core/indexes/base.py\", line 3621, in get_loc\n    return self._engine.get_loc(casted_key)\n  File \"pandas/_libs/index.pyx\", line 136, in pandas._libs.index.IndexEngine.get_loc\n  File \"pandas/_libs/index.pyx\", line 163, in pandas._libs.index.IndexEngine.get_loc\n  File \"pandas/_libs/hashtable_class_helper.pxi\", line 5198, in pandas._libs.hashtable.PyObjectHashTable.get_item\n  File \"pandas/_libs/hashtable_class_helper.pxi\", line 5206, in pandas._libs.hashtable.PyObjectHashTable.get_item\nKeyError: 'Date'\n\nThe above exception was the direct cause of the following exception:\n\nTraceback (most recent call last):\n  File \"/home/victordibia/projects/projectlida/lida/lib/lida/modules/executor.py\", line 144, in execute\n    exec(code, ex_locals)\n  File \"<string>\", line 17, in <module>\n  File \"<string>\", line 5, in plot\n  File \"/home/victordibia/.local/lib/python3.9/site-packages/pandas/core/frame.py\", line 3505, in __getitem__\n    indexer = self.columns.get_loc(key)\n  File \"/home/victordibia/.local/lib/python3.9/site-packages/pandas/core/indexes/base.py\", line 3623, in get_loc\n    raise KeyError(key) from err\nKeyError: 'Date'\n"}}], [{"spec": null, "status": false, "raster": null, "code": "import matplotlib.pyplot as plt\nimport pandas as pd\n\ndef plot(data: pd.DataFrame):\n    data['Date'] = pd.to_datetime(data['Date'], errors='coerce')\n    data = data[pd.notna(data['Date'])]\n    \n    plt.hist(data['Volume'], bins=50, color='blue', alpha=0.7)\n    plt.axvline(data['Volume'].median(), color='red', linestyle='dashed', linewidth=2, label=f\"Median: {data['Volume'].median():.2f}\")\n    plt.xlabel('Trading Volume')\n    plt.ylabel('Frequency')\n    plt.title('What is the distribution of trading volumes for the S&P 500 index?', wrap=True)\n    plt.legend()\n    return plt;\n\nchart = plot(data)", "library": "matplotlib", "error": {"message": "'Date'", "traceback": "Traceback (most recent call last):\n  File \"/home/victordibia/.local/lib/python3.9/site-packages/pandas/core/indexes/base.py\", line 3621, in get_loc\n    return self._engine.get_loc(casted_key)\n  File \"pandas/_libs/index.pyx\", line 136, in pandas._libs.index.IndexEngine.get_loc\n  File \"pandas/_libs/index.pyx\", line 163, in pandas._libs.index.IndexEngine.get_loc\n  File \"pandas/_libs/hashtable_class_helper.pxi\", line 5198, in pandas._libs.hashtable.PyObjectHashTable.get_item\n  File \"pandas/_libs/hashtable_class_helper.pxi\", line 5206, in pandas._libs.hashtable.PyObjectHashTable.get_item\nKeyError: 'Date'\n\nThe above exception was the direct cause of the following exception:\n\nTraceback (most recent call last):\n  File \"/home/victordibia/projects/projectlida/lida/lib/lida/modules/executor.py\", line 144, in execute\n    exec(code, ex_locals)\n  File \"<string>\", line 16, in <module>\n  File \"<string>\", line 5, in plot\n  File \"/home/victordibia/.local/lib/python3.9/site-packages/pandas/core/frame.py\", line 3505, in __getitem__\n    indexer = self.columns.get_loc(key)\n  File \"/home/victordibia/.local/lib/python3.9/site-packages/pandas/core/indexes/base.py\", line 3623, in get_loc\n    raise KeyError(key) from err\nKeyError: 'Date'\n"}}], [{"spec": null, "status": false, "raster": null, "code": "import matplotlib.pyplot as plt\nimport pandas as pd\n\ndef plot(data: pd.DataFrame):\n    data['Date'] = pd.to_datetime(data['Date'], errors='coerce')\n    data = data[pd.notna(data['Date'])]\n    data['Daily_Change'] = data['Close'].diff()\n    \n    fig, ax = plt.subplots()\n    ax.boxplot(data['Daily_Change'].dropna(), vert=False)\n    ax.set_xlabel('Daily Change')\n    ax.set_yticklabels(['S&P 500'])\n    plt.title('What is the distribution of daily changes in the S&P 500 index?', wrap=True)\n    \n    return plt;\n\nchart = plot(data)", "library": "matplotlib", "error": {"message": "'Date'", "traceback": "Traceback (most recent call last):\n  File \"/home/victordibia/.local/lib/python3.9/site-packages/pandas/core/indexes/base.py\", line 3621, in get_loc\n    return self._engine.get_loc(casted_key)\n  File \"pandas/_libs/index.pyx\", line 136, in pandas._libs.index.IndexEngine.get_loc\n  File \"pandas/_libs/index.pyx\", line 163, in pandas._libs.index.IndexEngine.get_loc\n  File \"pandas/_libs/hashtable_class_helper.pxi\", line 5198, in pandas._libs.hashtable.PyObjectHashTable.get_item\n  File \"pandas/_libs/hashtable_class_helper.pxi\", line 5206, in pandas._libs.hashtable.PyObjectHashTable.get_item\nKeyError: 'Date'\n\nThe above exception was the direct cause of the following exception:\n\nTraceback (most recent call last):\n  File \"/home/victordibia/projects/projectlida/lida/lib/lida/modules/executor.py\", line 144, in execute\n    exec(code, ex_locals)\n  File \"<string>\", line 17, in <module>\n  File \"<string>\", line 5, in plot\n  File \"/home/victordibia/.local/lib/python3.9/site-packages/pandas/core/frame.py\", line 3505, in __getitem__\n    indexer = self.columns.get_loc(key)\n  File \"/home/victordibia/.local/lib/python3.9/site-packages/pandas/core/indexes/base.py\", line 3623, in get_loc\n    raise KeyError(key) from err\nKeyError: 'Date'\n"}}]]}